<robot name="onshape">
    <link name="servomg996r">
        <visual>
            <origin xyz="0 0 0" rpy="0 -0 0"/>
            <geometry>
                <mesh filename="package://src/scara_description/meshes/servomg996r.stl"/>
            </geometry>
            <material name="servomg996r_material">
                <color rgba="0.61568627450980395466 0.81176470588235294379 0.92941176470588238168 1.0"/>
            </material>
        </visual>
        <collision>
            <origin xyz="0 0 0" rpy="0 -0 0"/>
            <geometry>
                <mesh filename="package://src/scara_description/meshes/servomg996r.stl"/>
            </geometry>
        </collision>
        <inertial>
            <origin xyz="0 0 0"/>
            <mass value="0"/>
            <inertia ixx="0" ixy="0" ixz="0" iyy="0" iyz="0" izz="0"/>
        </inertial>
    </link>
    <link name="first_link">
        <visual>
            <origin xyz="-7.1557343384043292644e-18 0.0099999999999999915345 0.047499999999999993616"
                    rpy="3.141592653589793116 -0 9.9276377748302604912e-18"/>
            <geometry>
                <mesh filename="package://src/scara_description/meshes/first_link.stl"/>
            </geometry>
            <material name="first_link_material">
                <color rgba="0.64705882352941179736 0.64705882352941179736 0.64705882352941179736 1.0"/>
            </material>
        </visual>
        <collision>
            <origin xyz="-7.1557343384043292644e-18 0.0099999999999999915345 0.047499999999999993616"
                    rpy="3.141592653589793116 -0 9.9276377748302604912e-18"/>
            <geometry>
                <mesh filename="package://src/scara_description/meshes/first_link.stl"/>
            </geometry>
        </collision>
        <inertial>
            <origin xyz="0 0 0"/>
            <mass value="0"/>
            <inertia ixx="0" ixy="0" ixz="0" iyy="0" iyz="0" izz="0"/>
        </inertial>
    </link>
    <link name="second_link">
        <visual>
            <origin xyz="0.00049999999999999740832 0.069749999999999978684 0.1034999999999999809"
                    rpy="3.141592653589793116 -0 7.9615434664501508339e-18"/>
            <geometry>
                <mesh filename="package://src/scara_description/meshes/second_link.stl"/>
            </geometry>
            <material name="second_link_material">
                <color rgba="0.24313725490196078094 0.24313725490196078094 1 1.0"/>
            </material>
        </visual>
        <collision>
            <origin xyz="0.00049999999999999740832 0.069749999999999978684 0.1034999999999999809"
                    rpy="3.141592653589793116 -0 7.9615434664501508339e-18"/>
            <geometry>
                <mesh filename="package://src/scara_description/meshes/second_link.stl"/>
            </geometry>
        </collision>
        <inertial>
            <origin xyz="0 0 0"/>
            <mass value="0"/>
            <inertia ixx="0" ixy="0" ixz="0" iyy="0" iyz="0" izz="0"/>
        </inertial>
    </link>
    <link name="actuator">
        <visual>
            <origin xyz="-0.12158358959999999993 0.017826000000000001566 -0.091630000000000003113"
                    rpy="-2.4987600029461807733e-34 1.1100799929901239999e-16 -1.570796326794896558"/>
            <geometry>
                <mesh filename="package://src/scara_description/meshes/actuator.stl"/>
            </geometry>
            <material name="actuator_material">
                <color rgba="0.50196078431372548323 1 0.50196078431372548323 1.0"/>
            </material>
        </visual>
        <collision>
            <origin xyz="-0.12158358959999999993 0.017826000000000001566 -0.091630000000000003113"
                    rpy="-2.4987600029461807733e-34 1.1100799929901239999e-16 -1.570796326794896558"/>
            <geometry>
                <mesh filename="package://src/scara_description/meshes/actuator.stl"/>
            </geometry>
        </collision>
        <inertial>
            <origin xyz="0 0 0"/>
            <mass value="0"/>
            <inertia ixx="0" ixy="0" ixz="0" iyy="0" iyz="0" izz="0"/>
        </inertial>
    </link>
    <joint name="Slider_actuator" type="prismatic">
        <origin xyz="0.018325999999999991602 -0.051833589599999993491 0.018598077114628464024"
                rpy="-3.141592653589793116 -5.1171304803077346007e-18 -1.5707963267948961139"/>
        <parent link="second_link"/>
        <child link="actuator"/>
        <axis xyz="0 0 1"/>
        <limit effort="1" velocity="20"/>
        <joint_properties friction="0.0"/>
    </joint>
    <joint name="Revolute_firsttosecondlink" type="revolute">
        <origin xyz="-0.00050000000000000304617 -0.059750000000000011435 -0.055999999999999987288"
                rpy="1.7662033618514959478e-21 2.5217203946365817101e-22 -5.465863304373380401e-15"/>
        <parent link="first_link"/>
        <child link="second_link"/>
        <axis xyz="0 0 1"/>
        <limit effort="1" velocity="20"/>
        <joint_properties friction="0.0"/>
    </joint>
    <joint name="996_firstlink" type="revolute">
        <origin xyz="6.505213034913026604e-18 0.0099999999999999915345 0.047499999999999993616"
                rpy="3.141592653589793116 2.4637214511932053286e-22 0.10904934252795142613"/>
        <parent link="servomg996r"/>
        <child link="first_link"/>
        <axis xyz="0 0 1"/>
        <limit effort="1" velocity="20"/>
        <joint_properties friction="0.0"/>
    </joint>
</robot>